<!DOCTYPE html PUBLIC "-//W3C//DTD XHTML 1.1//EN" "https://www.w3.org/TR/xhtml11/DTD/xhtml11.dtd">
<html xmlns="https://www.w3.org/1999/xhtml">
<head>
<meta http-equiv="content-type" content="text/html; charset=UTF-8"/>
<title>TestNG Report</title>
<style type="text/css">table {margin-bottom:10px;border-collapse:collapse;empty-cells:show}th,td {border:1px solid #009;padding:.25em .5em}th {vertical-align:bottom}td {vertical-align:top}table a {font-weight:bold}.stripe td {background-color: #E6EBF9}.num {text-align:right}.passedodd td {background-color: #3F3}.passedeven td {background-color: #0A0}.skippedodd td {background-color: #DDD}.skippedeven td {background-color: #CCC}.failedodd td,.attn {background-color: #F33}.failedeven td,.stripe .attn {background-color: #D00}.stacktrace {white-space:pre;font-family:monospace}.totop {font-size:85%;text-align:center;border-bottom:2px solid #000}.invisible {display:none}</style>
</head>
<body>
<table>
<tr><th>Test</th><th># Passed</th><th># Skipped</th><th># Retried</th><th># Failed</th><th>Time (ms)</th><th>Included Groups</th><th>Excluded Groups</th></tr>
<tr><th colspan="8">Default suite</th></tr>
<tr><td><a href="#t0">Default test</a></td><td class="num">0</td><td class="num">0</td><td class="num">0</td><td class="num attn">6</td><td class="num">2,779</td><td></td><td></td></tr>
</table>
<table id='summary'><thead><tr><th>Class</th><th>Method</th><th>Start</th><th>Time (ms)</th></tr></thead><tbody><tr><th colspan="4">Default suite</th></tr></tbody><tbody id="t0"><tr><th colspan="4">Default test &#8212; failed</th></tr><tr class="failedeven"><td rowspan="6">com.umr.apitesting.test.PracticalApiTest</td><td><a href="#m0">testCreateUser</a></td><td rowspan="1">1732649941804</td><td rowspan="1">1505</td></tr><tr class="failedeven"><td><a href="#m1">testGetCountry</a></td><td rowspan="1">1732649943318</td><td rowspan="1">428</td></tr><tr class="failedeven"><td><a href="#m2">testGetPost</a></td><td rowspan="1">1732649943752</td><td rowspan="1">188</td></tr><tr class="failedeven"><td><a href="#m3">testGetRepoInfo</a></td><td rowspan="1">1732649943942</td><td rowspan="1">279</td></tr><tr class="failedeven"><td><a href="#m4">testGetUser</a></td><td rowspan="1">1732649944222</td><td rowspan="1">153</td></tr><tr class="failedeven"><td><a href="#m5">testGetWeather</a></td><td rowspan="1">1732649944377</td><td rowspan="1">150</td></tr></tbody>
</table>
<h2>Default test</h2><h3 id="m0">com.umr.apitesting.test.PracticalApiTest#testCreateUser</h3><table class="result"><tr><th>Exception</th></tr><tr><td><div class="stacktrace">java.lang.RuntimeException: Test execution failed
	at com.umr.apitesting.core.executor.TestExecutor.executeTest(TestExecutor.java:45)
	at com.umr.apitesting.test.PracticalApiTest.testCreateUser(PracticalApiTest.java:26)
	at java.base/jdk.internal.reflect.DirectMethodHandleAccessor.invoke(DirectMethodHandleAccessor.java:103)
	at java.base/java.lang.reflect.Method.invoke(Method.java:580)
	at org.testng.internal.invokers.MethodInvocationHelper.invokeMethod(MethodInvocationHelper.java:139)
	at org.testng.internal.invokers.TestInvoker.invokeMethod(TestInvoker.java:677)
	at org.testng.internal.invokers.TestInvoker.invokeTestMethod(TestInvoker.java:221)
	at org.testng.internal.invokers.MethodRunner.runInSequence(MethodRunner.java:50)
	at org.testng.internal.invokers.TestInvoker$MethodInvocationAgent.invoke(TestInvoker.java:969)
	at org.testng.internal.invokers.TestInvoker.invokeTestMethods(TestInvoker.java:194)
	at org.testng.internal.invokers.TestMethodWorker.invokeTestMethods(TestMethodWorker.java:148)
	at org.testng.internal.invokers.TestMethodWorker.run(TestMethodWorker.java:128)
	at java.base/java.util.ArrayList.forEach(ArrayList.java:1596)
	at org.testng.TestRunner.privateRun(TestRunner.java:829)
	at org.testng.TestRunner.run(TestRunner.java:602)
	at org.testng.SuiteRunner.runTest(SuiteRunner.java:437)
	at org.testng.SuiteRunner.runSequentially(SuiteRunner.java:431)
	at org.testng.SuiteRunner.privateRun(SuiteRunner.java:391)
	at org.testng.SuiteRunner.run(SuiteRunner.java:330)
	at org.testng.SuiteRunnerWorker.runSuite(SuiteRunnerWorker.java:52)
	at org.testng.SuiteRunnerWorker.run(SuiteRunnerWorker.java:95)
	at org.testng.TestNG.runSuitesSequentially(TestNG.java:1256)
	at org.testng.TestNG.runSuitesLocally(TestNG.java:1176)
	at org.testng.TestNG.runSuites(TestNG.java:1099)
	at org.testng.TestNG.run(TestNG.java:1067)
	at org.testng.remote.AbstractRemoteTestNG.run(AbstractRemoteTestNG.java:115)
	at org.testng.remote.RemoteTestNG.initAndRun(RemoteTestNG.java:293)
	at org.testng.remote.RemoteTestNG.main(RemoteTestNG.java:91)
Caused by: java.lang.RuntimeException: Test failed at keyword: POST
	at com.umr.apitesting.core.executor.TestExecutor.executeTest(TestExecutor.java:39)
	... 27 more
</div></td></tr></table><p class="totop"><a href="#summary">back to summary</a></p>
<h3 id="m1">com.umr.apitesting.test.PracticalApiTest#testGetCountry</h3><table class="result"><tr><th>Exception</th></tr><tr><td><div class="stacktrace">java.lang.RuntimeException: Test execution failed
	at com.umr.apitesting.core.executor.TestExecutor.executeTest(TestExecutor.java:45)
	at com.umr.apitesting.test.PracticalApiTest.testGetCountry(PracticalApiTest.java:36)
	at java.base/jdk.internal.reflect.DirectMethodHandleAccessor.invoke(DirectMethodHandleAccessor.java:103)
	at java.base/java.lang.reflect.Method.invoke(Method.java:580)
	at org.testng.internal.invokers.MethodInvocationHelper.invokeMethod(MethodInvocationHelper.java:139)
	at org.testng.internal.invokers.TestInvoker.invokeMethod(TestInvoker.java:677)
	at org.testng.internal.invokers.TestInvoker.invokeTestMethod(TestInvoker.java:221)
	at org.testng.internal.invokers.MethodRunner.runInSequence(MethodRunner.java:50)
	at org.testng.internal.invokers.TestInvoker$MethodInvocationAgent.invoke(TestInvoker.java:969)
	at org.testng.internal.invokers.TestInvoker.invokeTestMethods(TestInvoker.java:194)
	at org.testng.internal.invokers.TestMethodWorker.invokeTestMethods(TestMethodWorker.java:148)
	at org.testng.internal.invokers.TestMethodWorker.run(TestMethodWorker.java:128)
	at java.base/java.util.ArrayList.forEach(ArrayList.java:1596)
	at org.testng.TestRunner.privateRun(TestRunner.java:829)
	at org.testng.TestRunner.run(TestRunner.java:602)
	at org.testng.SuiteRunner.runTest(SuiteRunner.java:437)
	at org.testng.SuiteRunner.runSequentially(SuiteRunner.java:431)
	at org.testng.SuiteRunner.privateRun(SuiteRunner.java:391)
	at org.testng.SuiteRunner.run(SuiteRunner.java:330)
	at org.testng.SuiteRunnerWorker.runSuite(SuiteRunnerWorker.java:52)
	at org.testng.SuiteRunnerWorker.run(SuiteRunnerWorker.java:95)
	at org.testng.TestNG.runSuitesSequentially(TestNG.java:1256)
	at org.testng.TestNG.runSuitesLocally(TestNG.java:1176)
	at org.testng.TestNG.runSuites(TestNG.java:1099)
	at org.testng.TestNG.run(TestNG.java:1067)
	at org.testng.remote.AbstractRemoteTestNG.run(AbstractRemoteTestNG.java:115)
	at org.testng.remote.RemoteTestNG.initAndRun(RemoteTestNG.java:293)
	at org.testng.remote.RemoteTestNG.main(RemoteTestNG.java:91)
Caused by: java.lang.RuntimeException: Test failed at keyword: VERIFY_STATUS
	at com.umr.apitesting.core.executor.TestExecutor.executeTest(TestExecutor.java:39)
	... 27 more
</div></td></tr></table><p class="totop"><a href="#summary">back to summary</a></p>
<h3 id="m2">com.umr.apitesting.test.PracticalApiTest#testGetPost</h3><table class="result"><tr><th>Exception</th></tr><tr><td><div class="stacktrace">java.lang.RuntimeException: Test execution failed
	at com.umr.apitesting.core.executor.TestExecutor.executeTest(TestExecutor.java:45)
	at com.umr.apitesting.test.PracticalApiTest.testGetPost(PracticalApiTest.java:21)
	at java.base/jdk.internal.reflect.DirectMethodHandleAccessor.invoke(DirectMethodHandleAccessor.java:103)
	at java.base/java.lang.reflect.Method.invoke(Method.java:580)
	at org.testng.internal.invokers.MethodInvocationHelper.invokeMethod(MethodInvocationHelper.java:139)
	at org.testng.internal.invokers.TestInvoker.invokeMethod(TestInvoker.java:677)
	at org.testng.internal.invokers.TestInvoker.invokeTestMethod(TestInvoker.java:221)
	at org.testng.internal.invokers.MethodRunner.runInSequence(MethodRunner.java:50)
	at org.testng.internal.invokers.TestInvoker$MethodInvocationAgent.invoke(TestInvoker.java:969)
	at org.testng.internal.invokers.TestInvoker.invokeTestMethods(TestInvoker.java:194)
	at org.testng.internal.invokers.TestMethodWorker.invokeTestMethods(TestMethodWorker.java:148)
	at org.testng.internal.invokers.TestMethodWorker.run(TestMethodWorker.java:128)
	at java.base/java.util.ArrayList.forEach(ArrayList.java:1596)
	at org.testng.TestRunner.privateRun(TestRunner.java:829)
	at org.testng.TestRunner.run(TestRunner.java:602)
	at org.testng.SuiteRunner.runTest(SuiteRunner.java:437)
	at org.testng.SuiteRunner.runSequentially(SuiteRunner.java:431)
	at org.testng.SuiteRunner.privateRun(SuiteRunner.java:391)
	at org.testng.SuiteRunner.run(SuiteRunner.java:330)
	at org.testng.SuiteRunnerWorker.runSuite(SuiteRunnerWorker.java:52)
	at org.testng.SuiteRunnerWorker.run(SuiteRunnerWorker.java:95)
	at org.testng.TestNG.runSuitesSequentially(TestNG.java:1256)
	at org.testng.TestNG.runSuitesLocally(TestNG.java:1176)
	at org.testng.TestNG.runSuites(TestNG.java:1099)
	at org.testng.TestNG.run(TestNG.java:1067)
	at org.testng.remote.AbstractRemoteTestNG.run(AbstractRemoteTestNG.java:115)
	at org.testng.remote.RemoteTestNG.initAndRun(RemoteTestNG.java:293)
	at org.testng.remote.RemoteTestNG.main(RemoteTestNG.java:91)
Caused by: java.lang.RuntimeException: Test failed at keyword: VERIFY_STATUS
	at com.umr.apitesting.core.executor.TestExecutor.executeTest(TestExecutor.java:39)
	... 27 more
</div></td></tr></table><p class="totop"><a href="#summary">back to summary</a></p>
<h3 id="m3">com.umr.apitesting.test.PracticalApiTest#testGetRepoInfo</h3><table class="result"><tr><th>Exception</th></tr><tr><td><div class="stacktrace">java.lang.RuntimeException: Test execution failed
	at com.umr.apitesting.core.executor.TestExecutor.executeTest(TestExecutor.java:45)
	at com.umr.apitesting.test.PracticalApiTest.testGetRepoInfo(PracticalApiTest.java:46)
	at java.base/jdk.internal.reflect.DirectMethodHandleAccessor.invoke(DirectMethodHandleAccessor.java:103)
	at java.base/java.lang.reflect.Method.invoke(Method.java:580)
	at org.testng.internal.invokers.MethodInvocationHelper.invokeMethod(MethodInvocationHelper.java:139)
	at org.testng.internal.invokers.TestInvoker.invokeMethod(TestInvoker.java:677)
	at org.testng.internal.invokers.TestInvoker.invokeTestMethod(TestInvoker.java:221)
	at org.testng.internal.invokers.MethodRunner.runInSequence(MethodRunner.java:50)
	at org.testng.internal.invokers.TestInvoker$MethodInvocationAgent.invoke(TestInvoker.java:969)
	at org.testng.internal.invokers.TestInvoker.invokeTestMethods(TestInvoker.java:194)
	at org.testng.internal.invokers.TestMethodWorker.invokeTestMethods(TestMethodWorker.java:148)
	at org.testng.internal.invokers.TestMethodWorker.run(TestMethodWorker.java:128)
	at java.base/java.util.ArrayList.forEach(ArrayList.java:1596)
	at org.testng.TestRunner.privateRun(TestRunner.java:829)
	at org.testng.TestRunner.run(TestRunner.java:602)
	at org.testng.SuiteRunner.runTest(SuiteRunner.java:437)
	at org.testng.SuiteRunner.runSequentially(SuiteRunner.java:431)
	at org.testng.SuiteRunner.privateRun(SuiteRunner.java:391)
	at org.testng.SuiteRunner.run(SuiteRunner.java:330)
	at org.testng.SuiteRunnerWorker.runSuite(SuiteRunnerWorker.java:52)
	at org.testng.SuiteRunnerWorker.run(SuiteRunnerWorker.java:95)
	at org.testng.TestNG.runSuitesSequentially(TestNG.java:1256)
	at org.testng.TestNG.runSuitesLocally(TestNG.java:1176)
	at org.testng.TestNG.runSuites(TestNG.java:1099)
	at org.testng.TestNG.run(TestNG.java:1067)
	at org.testng.remote.AbstractRemoteTestNG.run(AbstractRemoteTestNG.java:115)
	at org.testng.remote.RemoteTestNG.initAndRun(RemoteTestNG.java:293)
	at org.testng.remote.RemoteTestNG.main(RemoteTestNG.java:91)
Caused by: java.lang.RuntimeException: Test failed at keyword: VERIFY_STATUS
	at com.umr.apitesting.core.executor.TestExecutor.executeTest(TestExecutor.java:39)
	... 27 more
</div></td></tr></table><p class="totop"><a href="#summary">back to summary</a></p>
<h3 id="m4">com.umr.apitesting.test.PracticalApiTest#testGetUser</h3><table class="result"><tr><th>Exception</th></tr><tr><td><div class="stacktrace">java.lang.RuntimeException: Test execution failed
	at com.umr.apitesting.core.executor.TestExecutor.executeTest(TestExecutor.java:45)
	at com.umr.apitesting.test.PracticalApiTest.testGetUser(PracticalApiTest.java:31)
	at java.base/jdk.internal.reflect.DirectMethodHandleAccessor.invoke(DirectMethodHandleAccessor.java:103)
	at java.base/java.lang.reflect.Method.invoke(Method.java:580)
	at org.testng.internal.invokers.MethodInvocationHelper.invokeMethod(MethodInvocationHelper.java:139)
	at org.testng.internal.invokers.TestInvoker.invokeMethod(TestInvoker.java:677)
	at org.testng.internal.invokers.TestInvoker.invokeTestMethod(TestInvoker.java:221)
	at org.testng.internal.invokers.MethodRunner.runInSequence(MethodRunner.java:50)
	at org.testng.internal.invokers.TestInvoker$MethodInvocationAgent.invoke(TestInvoker.java:969)
	at org.testng.internal.invokers.TestInvoker.invokeTestMethods(TestInvoker.java:194)
	at org.testng.internal.invokers.TestMethodWorker.invokeTestMethods(TestMethodWorker.java:148)
	at org.testng.internal.invokers.TestMethodWorker.run(TestMethodWorker.java:128)
	at java.base/java.util.ArrayList.forEach(ArrayList.java:1596)
	at org.testng.TestRunner.privateRun(TestRunner.java:829)
	at org.testng.TestRunner.run(TestRunner.java:602)
	at org.testng.SuiteRunner.runTest(SuiteRunner.java:437)
	at org.testng.SuiteRunner.runSequentially(SuiteRunner.java:431)
	at org.testng.SuiteRunner.privateRun(SuiteRunner.java:391)
	at org.testng.SuiteRunner.run(SuiteRunner.java:330)
	at org.testng.SuiteRunnerWorker.runSuite(SuiteRunnerWorker.java:52)
	at org.testng.SuiteRunnerWorker.run(SuiteRunnerWorker.java:95)
	at org.testng.TestNG.runSuitesSequentially(TestNG.java:1256)
	at org.testng.TestNG.runSuitesLocally(TestNG.java:1176)
	at org.testng.TestNG.runSuites(TestNG.java:1099)
	at org.testng.TestNG.run(TestNG.java:1067)
	at org.testng.remote.AbstractRemoteTestNG.run(AbstractRemoteTestNG.java:115)
	at org.testng.remote.RemoteTestNG.initAndRun(RemoteTestNG.java:293)
	at org.testng.remote.RemoteTestNG.main(RemoteTestNG.java:91)
Caused by: java.lang.RuntimeException: Test failed at keyword: VERIFY_STATUS
	at com.umr.apitesting.core.executor.TestExecutor.executeTest(TestExecutor.java:39)
	... 27 more
</div></td></tr></table><p class="totop"><a href="#summary">back to summary</a></p>
<h3 id="m5">com.umr.apitesting.test.PracticalApiTest#testGetWeather</h3><table class="result"><tr><th>Exception</th></tr><tr><td><div class="stacktrace">java.lang.RuntimeException: Test execution failed
	at com.umr.apitesting.core.executor.TestExecutor.executeTest(TestExecutor.java:45)
	at com.umr.apitesting.test.PracticalApiTest.testGetWeather(PracticalApiTest.java:41)
	at java.base/jdk.internal.reflect.DirectMethodHandleAccessor.invoke(DirectMethodHandleAccessor.java:103)
	at java.base/java.lang.reflect.Method.invoke(Method.java:580)
	at org.testng.internal.invokers.MethodInvocationHelper.invokeMethod(MethodInvocationHelper.java:139)
	at org.testng.internal.invokers.TestInvoker.invokeMethod(TestInvoker.java:677)
	at org.testng.internal.invokers.TestInvoker.invokeTestMethod(TestInvoker.java:221)
	at org.testng.internal.invokers.MethodRunner.runInSequence(MethodRunner.java:50)
	at org.testng.internal.invokers.TestInvoker$MethodInvocationAgent.invoke(TestInvoker.java:969)
	at org.testng.internal.invokers.TestInvoker.invokeTestMethods(TestInvoker.java:194)
	at org.testng.internal.invokers.TestMethodWorker.invokeTestMethods(TestMethodWorker.java:148)
	at org.testng.internal.invokers.TestMethodWorker.run(TestMethodWorker.java:128)
	at java.base/java.util.ArrayList.forEach(ArrayList.java:1596)
	at org.testng.TestRunner.privateRun(TestRunner.java:829)
	at org.testng.TestRunner.run(TestRunner.java:602)
	at org.testng.SuiteRunner.runTest(SuiteRunner.java:437)
	at org.testng.SuiteRunner.runSequentially(SuiteRunner.java:431)
	at org.testng.SuiteRunner.privateRun(SuiteRunner.java:391)
	at org.testng.SuiteRunner.run(SuiteRunner.java:330)
	at org.testng.SuiteRunnerWorker.runSuite(SuiteRunnerWorker.java:52)
	at org.testng.SuiteRunnerWorker.run(SuiteRunnerWorker.java:95)
	at org.testng.TestNG.runSuitesSequentially(TestNG.java:1256)
	at org.testng.TestNG.runSuitesLocally(TestNG.java:1176)
	at org.testng.TestNG.runSuites(TestNG.java:1099)
	at org.testng.TestNG.run(TestNG.java:1067)
	at org.testng.remote.AbstractRemoteTestNG.run(AbstractRemoteTestNG.java:115)
	at org.testng.remote.RemoteTestNG.initAndRun(RemoteTestNG.java:293)
	at org.testng.remote.RemoteTestNG.main(RemoteTestNG.java:91)
Caused by: java.lang.RuntimeException: Test failed at keyword: VERIFY_STATUS
	at com.umr.apitesting.core.executor.TestExecutor.executeTest(TestExecutor.java:39)
	... 27 more
</div></td></tr></table><p class="totop"><a href="#summary">back to summary</a></p>
</body>
</html>
