<?xml version="1.0" encoding="UTF-8"?>
<testng-results ignored="0" total="6" passed="0" failed="6" skipped="0">
  <reporter-output>
  </reporter-output>
  <suite started-at="2024-11-26T14:39:01 EST" name="Default suite" finished-at="2024-11-26T14:39:04 EST" duration-ms="2779">
    <groups>
    </groups>
    <test started-at="2024-11-26T14:39:01 EST" name="Default test" finished-at="2024-11-26T14:39:04 EST" duration-ms="2779">
      <class name="com.umr.apitesting.test.PracticalApiTest">
        <test-method is-config="true" signature="setup()[pri:0, instance:com.umr.apitesting.test.PracticalApiTest@25f9407e]" started-at="2024-11-26T14:39:01 EST" name="setup" finished-at="2024-11-26T14:39:01 EST" duration-ms="21" status="PASS">
          <reporter-output>
          </reporter-output>
        </test-method> <!-- setup -->
        <test-method signature="testCreateUser()[pri:0, instance:com.umr.apitesting.test.PracticalApiTest@25f9407e]" started-at="2024-11-26T14:39:01 EST" name="testCreateUser" description="Create user using ReqRes API" finished-at="2024-11-26T14:39:03 EST" duration-ms="1505" status="FAIL">
          <exception class="java.lang.RuntimeException">
            <message>
              <![CDATA[Test execution failed]]>
            </message>
            <full-stacktrace>
              <![CDATA[java.lang.RuntimeException: Test execution failed
at com.umr.apitesting.core.executor.TestExecutor.executeTest(TestExecutor.java:45)
at com.umr.apitesting.test.PracticalApiTest.testCreateUser(PracticalApiTest.java:26)
at java.base/jdk.internal.reflect.DirectMethodHandleAccessor.invoke(DirectMethodHandleAccessor.java:103)
at java.base/java.lang.reflect.Method.invoke(Method.java:580)
at org.testng.internal.invokers.MethodInvocationHelper.invokeMethod(MethodInvocationHelper.java:139)
at org.testng.internal.invokers.TestInvoker.invokeMethod(TestInvoker.java:677)
at org.testng.internal.invokers.TestInvoker.invokeTestMethod(TestInvoker.java:221)
at org.testng.internal.invokers.MethodRunner.runInSequence(MethodRunner.java:50)
at org.testng.internal.invokers.TestInvoker$MethodInvocationAgent.invoke(TestInvoker.java:969)
at org.testng.internal.invokers.TestInvoker.invokeTestMethods(TestInvoker.java:194)
at org.testng.internal.invokers.TestMethodWorker.invokeTestMethods(TestMethodWorker.java:148)
at org.testng.internal.invokers.TestMethodWorker.run(TestMethodWorker.java:128)
at java.base/java.util.ArrayList.forEach(ArrayList.java:1596)
at org.testng.TestRunner.privateRun(TestRunner.java:829)
at org.testng.TestRunner.run(TestRunner.java:602)
at org.testng.SuiteRunner.runTest(SuiteRunner.java:437)
at org.testng.SuiteRunner.runSequentially(SuiteRunner.java:431)
at org.testng.SuiteRunner.privateRun(SuiteRunner.java:391)
at org.testng.SuiteRunner.run(SuiteRunner.java:330)
at org.testng.SuiteRunnerWorker.runSuite(SuiteRunnerWorker.java:52)
at org.testng.SuiteRunnerWorker.run(SuiteRunnerWorker.java:95)
at org.testng.TestNG.runSuitesSequentially(TestNG.java:1256)
at org.testng.TestNG.runSuitesLocally(TestNG.java:1176)
at org.testng.TestNG.runSuites(TestNG.java:1099)
at org.testng.TestNG.run(TestNG.java:1067)
at org.testng.remote.AbstractRemoteTestNG.run(AbstractRemoteTestNG.java:115)
at org.testng.remote.RemoteTestNG.initAndRun(RemoteTestNG.java:293)
at org.testng.remote.RemoteTestNG.main(RemoteTestNG.java:91)
Caused by: java.lang.RuntimeException: Test failed at keyword: POST
at com.umr.apitesting.core.executor.TestExecutor.executeTest(TestExecutor.java:39)
... 27 more
]]>
            </full-stacktrace>
          </exception> <!-- java.lang.RuntimeException -->
          <reporter-output>
          </reporter-output>
        </test-method> <!-- testCreateUser -->
        <test-method signature="testGetCountry()[pri:0, instance:com.umr.apitesting.test.PracticalApiTest@25f9407e]" started-at="2024-11-26T14:39:03 EST" name="testGetCountry" description="Get country details" finished-at="2024-11-26T14:39:03 EST" duration-ms="428" status="FAIL">
          <exception class="java.lang.RuntimeException">
            <message>
              <![CDATA[Test execution failed]]>
            </message>
            <full-stacktrace>
              <![CDATA[java.lang.RuntimeException: Test execution failed
at com.umr.apitesting.core.executor.TestExecutor.executeTest(TestExecutor.java:45)
at com.umr.apitesting.test.PracticalApiTest.testGetCountry(PracticalApiTest.java:36)
at java.base/jdk.internal.reflect.DirectMethodHandleAccessor.invoke(DirectMethodHandleAccessor.java:103)
at java.base/java.lang.reflect.Method.invoke(Method.java:580)
at org.testng.internal.invokers.MethodInvocationHelper.invokeMethod(MethodInvocationHelper.java:139)
at org.testng.internal.invokers.TestInvoker.invokeMethod(TestInvoker.java:677)
at org.testng.internal.invokers.TestInvoker.invokeTestMethod(TestInvoker.java:221)
at org.testng.internal.invokers.MethodRunner.runInSequence(MethodRunner.java:50)
at org.testng.internal.invokers.TestInvoker$MethodInvocationAgent.invoke(TestInvoker.java:969)
at org.testng.internal.invokers.TestInvoker.invokeTestMethods(TestInvoker.java:194)
at org.testng.internal.invokers.TestMethodWorker.invokeTestMethods(TestMethodWorker.java:148)
at org.testng.internal.invokers.TestMethodWorker.run(TestMethodWorker.java:128)
at java.base/java.util.ArrayList.forEach(ArrayList.java:1596)
at org.testng.TestRunner.privateRun(TestRunner.java:829)
at org.testng.TestRunner.run(TestRunner.java:602)
at org.testng.SuiteRunner.runTest(SuiteRunner.java:437)
at org.testng.SuiteRunner.runSequentially(SuiteRunner.java:431)
at org.testng.SuiteRunner.privateRun(SuiteRunner.java:391)
at org.testng.SuiteRunner.run(SuiteRunner.java:330)
at org.testng.SuiteRunnerWorker.runSuite(SuiteRunnerWorker.java:52)
at org.testng.SuiteRunnerWorker.run(SuiteRunnerWorker.java:95)
at org.testng.TestNG.runSuitesSequentially(TestNG.java:1256)
at org.testng.TestNG.runSuitesLocally(TestNG.java:1176)
at org.testng.TestNG.runSuites(TestNG.java:1099)
at org.testng.TestNG.run(TestNG.java:1067)
at org.testng.remote.AbstractRemoteTestNG.run(AbstractRemoteTestNG.java:115)
at org.testng.remote.RemoteTestNG.initAndRun(RemoteTestNG.java:293)
at org.testng.remote.RemoteTestNG.main(RemoteTestNG.java:91)
Caused by: java.lang.RuntimeException: Test failed at keyword: VERIFY_STATUS
at com.umr.apitesting.core.executor.TestExecutor.executeTest(TestExecutor.java:39)
... 27 more
]]>
            </full-stacktrace>
          </exception> <!-- java.lang.RuntimeException -->
          <reporter-output>
          </reporter-output>
        </test-method> <!-- testGetCountry -->
        <test-method signature="testGetPost()[pri:0, instance:com.umr.apitesting.test.PracticalApiTest@25f9407e]" started-at="2024-11-26T14:39:03 EST" name="testGetPost" description="Get post details from JSONPlaceholder" finished-at="2024-11-26T14:39:03 EST" duration-ms="188" status="FAIL">
          <exception class="java.lang.RuntimeException">
            <message>
              <![CDATA[Test execution failed]]>
            </message>
            <full-stacktrace>
              <![CDATA[java.lang.RuntimeException: Test execution failed
at com.umr.apitesting.core.executor.TestExecutor.executeTest(TestExecutor.java:45)
at com.umr.apitesting.test.PracticalApiTest.testGetPost(PracticalApiTest.java:21)
at java.base/jdk.internal.reflect.DirectMethodHandleAccessor.invoke(DirectMethodHandleAccessor.java:103)
at java.base/java.lang.reflect.Method.invoke(Method.java:580)
at org.testng.internal.invokers.MethodInvocationHelper.invokeMethod(MethodInvocationHelper.java:139)
at org.testng.internal.invokers.TestInvoker.invokeMethod(TestInvoker.java:677)
at org.testng.internal.invokers.TestInvoker.invokeTestMethod(TestInvoker.java:221)
at org.testng.internal.invokers.MethodRunner.runInSequence(MethodRunner.java:50)
at org.testng.internal.invokers.TestInvoker$MethodInvocationAgent.invoke(TestInvoker.java:969)
at org.testng.internal.invokers.TestInvoker.invokeTestMethods(TestInvoker.java:194)
at org.testng.internal.invokers.TestMethodWorker.invokeTestMethods(TestMethodWorker.java:148)
at org.testng.internal.invokers.TestMethodWorker.run(TestMethodWorker.java:128)
at java.base/java.util.ArrayList.forEach(ArrayList.java:1596)
at org.testng.TestRunner.privateRun(TestRunner.java:829)
at org.testng.TestRunner.run(TestRunner.java:602)
at org.testng.SuiteRunner.runTest(SuiteRunner.java:437)
at org.testng.SuiteRunner.runSequentially(SuiteRunner.java:431)
at org.testng.SuiteRunner.privateRun(SuiteRunner.java:391)
at org.testng.SuiteRunner.run(SuiteRunner.java:330)
at org.testng.SuiteRunnerWorker.runSuite(SuiteRunnerWorker.java:52)
at org.testng.SuiteRunnerWorker.run(SuiteRunnerWorker.java:95)
at org.testng.TestNG.runSuitesSequentially(TestNG.java:1256)
at org.testng.TestNG.runSuitesLocally(TestNG.java:1176)
at org.testng.TestNG.runSuites(TestNG.java:1099)
at org.testng.TestNG.run(TestNG.java:1067)
at org.testng.remote.AbstractRemoteTestNG.run(AbstractRemoteTestNG.java:115)
at org.testng.remote.RemoteTestNG.initAndRun(RemoteTestNG.java:293)
at org.testng.remote.RemoteTestNG.main(RemoteTestNG.java:91)
Caused by: java.lang.RuntimeException: Test failed at keyword: VERIFY_STATUS
at com.umr.apitesting.core.executor.TestExecutor.executeTest(TestExecutor.java:39)
... 27 more
]]>
            </full-stacktrace>
          </exception> <!-- java.lang.RuntimeException -->
          <reporter-output>
          </reporter-output>
        </test-method> <!-- testGetPost -->
        <test-method signature="testGetRepoInfo()[pri:0, instance:com.umr.apitesting.test.PracticalApiTest@25f9407e]" started-at="2024-11-26T14:39:03 EST" name="testGetRepoInfo" description="Get GitHub repository info" finished-at="2024-11-26T14:39:04 EST" duration-ms="279" status="FAIL">
          <exception class="java.lang.RuntimeException">
            <message>
              <![CDATA[Test execution failed]]>
            </message>
            <full-stacktrace>
              <![CDATA[java.lang.RuntimeException: Test execution failed
at com.umr.apitesting.core.executor.TestExecutor.executeTest(TestExecutor.java:45)
at com.umr.apitesting.test.PracticalApiTest.testGetRepoInfo(PracticalApiTest.java:46)
at java.base/jdk.internal.reflect.DirectMethodHandleAccessor.invoke(DirectMethodHandleAccessor.java:103)
at java.base/java.lang.reflect.Method.invoke(Method.java:580)
at org.testng.internal.invokers.MethodInvocationHelper.invokeMethod(MethodInvocationHelper.java:139)
at org.testng.internal.invokers.TestInvoker.invokeMethod(TestInvoker.java:677)
at org.testng.internal.invokers.TestInvoker.invokeTestMethod(TestInvoker.java:221)
at org.testng.internal.invokers.MethodRunner.runInSequence(MethodRunner.java:50)
at org.testng.internal.invokers.TestInvoker$MethodInvocationAgent.invoke(TestInvoker.java:969)
at org.testng.internal.invokers.TestInvoker.invokeTestMethods(TestInvoker.java:194)
at org.testng.internal.invokers.TestMethodWorker.invokeTestMethods(TestMethodWorker.java:148)
at org.testng.internal.invokers.TestMethodWorker.run(TestMethodWorker.java:128)
at java.base/java.util.ArrayList.forEach(ArrayList.java:1596)
at org.testng.TestRunner.privateRun(TestRunner.java:829)
at org.testng.TestRunner.run(TestRunner.java:602)
at org.testng.SuiteRunner.runTest(SuiteRunner.java:437)
at org.testng.SuiteRunner.runSequentially(SuiteRunner.java:431)
at org.testng.SuiteRunner.privateRun(SuiteRunner.java:391)
at org.testng.SuiteRunner.run(SuiteRunner.java:330)
at org.testng.SuiteRunnerWorker.runSuite(SuiteRunnerWorker.java:52)
at org.testng.SuiteRunnerWorker.run(SuiteRunnerWorker.java:95)
at org.testng.TestNG.runSuitesSequentially(TestNG.java:1256)
at org.testng.TestNG.runSuitesLocally(TestNG.java:1176)
at org.testng.TestNG.runSuites(TestNG.java:1099)
at org.testng.TestNG.run(TestNG.java:1067)
at org.testng.remote.AbstractRemoteTestNG.run(AbstractRemoteTestNG.java:115)
at org.testng.remote.RemoteTestNG.initAndRun(RemoteTestNG.java:293)
at org.testng.remote.RemoteTestNG.main(RemoteTestNG.java:91)
Caused by: java.lang.RuntimeException: Test failed at keyword: VERIFY_STATUS
at com.umr.apitesting.core.executor.TestExecutor.executeTest(TestExecutor.java:39)
... 27 more
]]>
            </full-stacktrace>
          </exception> <!-- java.lang.RuntimeException -->
          <reporter-output>
          </reporter-output>
        </test-method> <!-- testGetRepoInfo -->
        <test-method signature="testGetUser()[pri:0, instance:com.umr.apitesting.test.PracticalApiTest@25f9407e]" started-at="2024-11-26T14:39:04 EST" name="testGetUser" description="Get user details from ReqRes" finished-at="2024-11-26T14:39:04 EST" duration-ms="153" status="FAIL">
          <exception class="java.lang.RuntimeException">
            <message>
              <![CDATA[Test execution failed]]>
            </message>
            <full-stacktrace>
              <![CDATA[java.lang.RuntimeException: Test execution failed
at com.umr.apitesting.core.executor.TestExecutor.executeTest(TestExecutor.java:45)
at com.umr.apitesting.test.PracticalApiTest.testGetUser(PracticalApiTest.java:31)
at java.base/jdk.internal.reflect.DirectMethodHandleAccessor.invoke(DirectMethodHandleAccessor.java:103)
at java.base/java.lang.reflect.Method.invoke(Method.java:580)
at org.testng.internal.invokers.MethodInvocationHelper.invokeMethod(MethodInvocationHelper.java:139)
at org.testng.internal.invokers.TestInvoker.invokeMethod(TestInvoker.java:677)
at org.testng.internal.invokers.TestInvoker.invokeTestMethod(TestInvoker.java:221)
at org.testng.internal.invokers.MethodRunner.runInSequence(MethodRunner.java:50)
at org.testng.internal.invokers.TestInvoker$MethodInvocationAgent.invoke(TestInvoker.java:969)
at org.testng.internal.invokers.TestInvoker.invokeTestMethods(TestInvoker.java:194)
at org.testng.internal.invokers.TestMethodWorker.invokeTestMethods(TestMethodWorker.java:148)
at org.testng.internal.invokers.TestMethodWorker.run(TestMethodWorker.java:128)
at java.base/java.util.ArrayList.forEach(ArrayList.java:1596)
at org.testng.TestRunner.privateRun(TestRunner.java:829)
at org.testng.TestRunner.run(TestRunner.java:602)
at org.testng.SuiteRunner.runTest(SuiteRunner.java:437)
at org.testng.SuiteRunner.runSequentially(SuiteRunner.java:431)
at org.testng.SuiteRunner.privateRun(SuiteRunner.java:391)
at org.testng.SuiteRunner.run(SuiteRunner.java:330)
at org.testng.SuiteRunnerWorker.runSuite(SuiteRunnerWorker.java:52)
at org.testng.SuiteRunnerWorker.run(SuiteRunnerWorker.java:95)
at org.testng.TestNG.runSuitesSequentially(TestNG.java:1256)
at org.testng.TestNG.runSuitesLocally(TestNG.java:1176)
at org.testng.TestNG.runSuites(TestNG.java:1099)
at org.testng.TestNG.run(TestNG.java:1067)
at org.testng.remote.AbstractRemoteTestNG.run(AbstractRemoteTestNG.java:115)
at org.testng.remote.RemoteTestNG.initAndRun(RemoteTestNG.java:293)
at org.testng.remote.RemoteTestNG.main(RemoteTestNG.java:91)
Caused by: java.lang.RuntimeException: Test failed at keyword: VERIFY_STATUS
at com.umr.apitesting.core.executor.TestExecutor.executeTest(TestExecutor.java:39)
... 27 more
]]>
            </full-stacktrace>
          </exception> <!-- java.lang.RuntimeException -->
          <reporter-output>
          </reporter-output>
        </test-method> <!-- testGetUser -->
        <test-method signature="testGetWeather()[pri:0, instance:com.umr.apitesting.test.PracticalApiTest@25f9407e]" started-at="2024-11-26T14:39:04 EST" name="testGetWeather" description="Get weather data" finished-at="2024-11-26T14:39:04 EST" duration-ms="150" status="FAIL">
          <exception class="java.lang.RuntimeException">
            <message>
              <![CDATA[Test execution failed]]>
            </message>
            <full-stacktrace>
              <![CDATA[java.lang.RuntimeException: Test execution failed
at com.umr.apitesting.core.executor.TestExecutor.executeTest(TestExecutor.java:45)
at com.umr.apitesting.test.PracticalApiTest.testGetWeather(PracticalApiTest.java:41)
at java.base/jdk.internal.reflect.DirectMethodHandleAccessor.invoke(DirectMethodHandleAccessor.java:103)
at java.base/java.lang.reflect.Method.invoke(Method.java:580)
at org.testng.internal.invokers.MethodInvocationHelper.invokeMethod(MethodInvocationHelper.java:139)
at org.testng.internal.invokers.TestInvoker.invokeMethod(TestInvoker.java:677)
at org.testng.internal.invokers.TestInvoker.invokeTestMethod(TestInvoker.java:221)
at org.testng.internal.invokers.MethodRunner.runInSequence(MethodRunner.java:50)
at org.testng.internal.invokers.TestInvoker$MethodInvocationAgent.invoke(TestInvoker.java:969)
at org.testng.internal.invokers.TestInvoker.invokeTestMethods(TestInvoker.java:194)
at org.testng.internal.invokers.TestMethodWorker.invokeTestMethods(TestMethodWorker.java:148)
at org.testng.internal.invokers.TestMethodWorker.run(TestMethodWorker.java:128)
at java.base/java.util.ArrayList.forEach(ArrayList.java:1596)
at org.testng.TestRunner.privateRun(TestRunner.java:829)
at org.testng.TestRunner.run(TestRunner.java:602)
at org.testng.SuiteRunner.runTest(SuiteRunner.java:437)
at org.testng.SuiteRunner.runSequentially(SuiteRunner.java:431)
at org.testng.SuiteRunner.privateRun(SuiteRunner.java:391)
at org.testng.SuiteRunner.run(SuiteRunner.java:330)
at org.testng.SuiteRunnerWorker.runSuite(SuiteRunnerWorker.java:52)
at org.testng.SuiteRunnerWorker.run(SuiteRunnerWorker.java:95)
at org.testng.TestNG.runSuitesSequentially(TestNG.java:1256)
at org.testng.TestNG.runSuitesLocally(TestNG.java:1176)
at org.testng.TestNG.runSuites(TestNG.java:1099)
at org.testng.TestNG.run(TestNG.java:1067)
at org.testng.remote.AbstractRemoteTestNG.run(AbstractRemoteTestNG.java:115)
at org.testng.remote.RemoteTestNG.initAndRun(RemoteTestNG.java:293)
at org.testng.remote.RemoteTestNG.main(RemoteTestNG.java:91)
Caused by: java.lang.RuntimeException: Test failed at keyword: VERIFY_STATUS
at com.umr.apitesting.core.executor.TestExecutor.executeTest(TestExecutor.java:39)
... 27 more
]]>
            </full-stacktrace>
          </exception> <!-- java.lang.RuntimeException -->
          <reporter-output>
          </reporter-output>
        </test-method> <!-- testGetWeather -->
      </class> <!-- com.umr.apitesting.test.PracticalApiTest -->
    </test> <!-- Default test -->
  </suite> <!-- Default suite -->
</testng-results>
